import { render, screen, fireEvent } from '@testing-library/react';
import { describe, it, expect, vi } from 'vitest';
import ErrorBoundary from '@/components/ErrorBoundary';

// Component that throws an error
const ThrowError = ({ shouldThrow }: { shouldThrow: boolean }) => {
  if (shouldThrow) {
    throw new Error('Test error');
  }
  return <div>No error</div>;
};

describe('ErrorBoundary', () => {
  it('renders children when there is no error', () => {
    render(
      <ErrorBoundary>
        <div>Test content</div>
      </ErrorBoundary>
    );

    expect(screen.getByText('Test content')).toBeInTheDocument();
  });

  it('renders error UI when there is an error', () => {
    // Suppress console.error for this test
    const consoleSpy = vi.spyOn(console, 'error').mockImplementation(() => {});

    render(
      <ErrorBoundary>
        <ThrowError shouldThrow={true} />
      </ErrorBoundary>
    );

    expect(screen.getByText('Something went wrong')).toBeInTheDocument();
    expect(screen.getByText('Try Again')).toBeInTheDocument();
    expect(screen.getByText('Go Home')).toBeInTheDocument();

    consoleSpy.mockRestore();
  });

  it('calls onError callback when error occurs', () => {
    const onError = vi.fn();
    const consoleSpy = vi.spyOn(console, 'error').mockImplementation(() => {});

    render(
      <ErrorBoundary onError={onError}>
        <ThrowError shouldThrow={true} />
      </ErrorBoundary>
    );

    expect(onError).toHaveBeenCalledWith(
      expect.any(Error),
      expect.objectContaining({
        componentStack: expect.any(String)
      })
    );

    consoleSpy.mockRestore();
  });

  it('renders custom fallback when provided', () => {
    const fallback = <div>Custom error message</div>;
    const consoleSpy = vi.spyOn(console, 'error').mockImplementation(() => {});

    render(
      <ErrorBoundary fallback={fallback}>
        <ThrowError shouldThrow={true} />
      </ErrorBoundary>
    );

    expect(screen.getByText('Custom error message')).toBeInTheDocument();

    consoleSpy.mockRestore();
  });

  it('resets error state when retry button is clicked', () => {
    const consoleSpy = vi.spyOn(console, 'error').mockImplementation(() => {});

    const { rerender } = render(
      <ErrorBoundary>
        <ThrowError shouldThrow={true} />
      </ErrorBoundary>
    );

    expect(screen.getByText('Something went wrong')).toBeInTheDocument();

    fireEvent.click(screen.getByText('Try Again'));

    // Re-render with no error
    rerender(
      <ErrorBoundary>
        <ThrowError shouldThrow={false} />
      </ErrorBoundary>
    );

    // The error boundary should still show the error UI until the component is unmounted and remounted
    expect(screen.getByText('Something went wrong')).toBeInTheDocument();

    consoleSpy.mockRestore();
  });

  it('navigates to home when go home button is clicked', () => {
    const consoleSpy = vi.spyOn(console, 'error').mockImplementation(() => {});
    const locationSpy = vi.spyOn(window, 'location', 'get').mockReturnValue({
      href: 'http://localhost:3000',
    } as Location);

    render(
      <ErrorBoundary>
        <ThrowError shouldThrow={true} />
      </ErrorBoundary>
    );

    fireEvent.click(screen.getByText('Go Home'));

    expect(window.location.href).toBe('/');

    consoleSpy.mockRestore();
    locationSpy.mockRestore();
  });
});
